{'nombre': 'MannyCalavera', 'idUsuario': 6924972L}
No hay ganadores
La solucion correcta era: La 2

Traceback (most recent call last):
  File "./main.py", line 226, in <module>
    main()
  File "./main.py", line 223, in main
    bot.polling(none_stop=True)
  File "/usr/local/lib/python2.7/dist-packages/telebot/__init__.py", line 171, in polling
    self.__threaded_polling(none_stop, interval, timeout)
  File "/usr/local/lib/python2.7/dist-packages/telebot/__init__.py", line 194, in __threaded_polling
    polling_thread.raise_exceptions()
  File "/usr/local/lib/python2.7/dist-packages/telebot/util.py", line 72, in raise_exceptions
    six.reraise(self.exc_info[0], self.exc_info[1], self.exc_info[2])
  File "/usr/local/lib/python2.7/dist-packages/telebot/util.py", line 53, in run
    task(*args, **kwargs)
  File "/usr/local/lib/python2.7/dist-packages/telebot/__init__.py", line 120, in __retrieve_updates
    updates = self.get_updates(offset=(self.last_update_id + 1), timeout=timeout)
  File "/usr/local/lib/python2.7/dist-packages/telebot/__init__.py", line 90, in get_updates
    json_updates = apihelper.get_updates(self.token, offset, limit, timeout)
  File "/usr/local/lib/python2.7/dist-packages/telebot/apihelper.py", line 129, in get_updates
    return _make_request(token, method_url, params=payload)
  File "/usr/local/lib/python2.7/dist-packages/telebot/apihelper.py", line 26, in _make_request
    result = requests.request(method, request_url, params=params, files=files)
  File "/usr/local/lib/python2.7/dist-packages/requests-2.9.1-py2.7.egg/requests/api.py", line 53, in request
    return session.request(method=method, url=url, **kwargs)
  File "/usr/local/lib/python2.7/dist-packages/requests-2.9.1-py2.7.egg/requests/sessions.py", line 468, in request
    resp = self.send(prep, **send_kwargs)
  File "/usr/local/lib/python2.7/dist-packages/requests-2.9.1-py2.7.egg/requests/sessions.py", line 576, in send
    r = adapter.send(request, **kwargs)
  File "/usr/local/lib/python2.7/dist-packages/requests-2.9.1-py2.7.egg/requests/adapters.py", line 447, in send
    raise SSLError(e, request=request)
requests.exceptions.SSLError: ("bad handshake: SysCallError(104, 'ECONNRESET')",)
2016-04-26 10:42:29,659 (__init__.py:199 MainThread) ERROR - TeleBot: "A request to the Telegram API was unsuccessful. The server returned HTTP 502 Bad Gateway. Response body:
[<html>
<head><title>502 Bad Gateway</title></head>
<body bgcolor="white">
<center><h1>502 Bad Gateway</h1></center>
<hr><center>nginx/1.6.2</center>
</body>
</html>
]"
2016-04-26 10:42:30,491 (__init__.py:199 MainThread) ERROR - TeleBot: "A request to the Telegram API was unsuccessful. The server returned HTTP 502 Bad Gateway. Response body:
[<html>
<head><title>502 Bad Gateway</title></head>
<body bgcolor="white">
<center><h1>502 Bad Gateway</h1></center>
<hr><center>nginx/1.6.2</center>
</body>
</html>
]"
2016-04-26 10:42:31,511 (__init__.py:199 MainThread) ERROR - TeleBot: "A request to the Telegram API was unsuccessful. The server returned HTTP 502 Bad Gateway. Response body:
[<html>
<head><title>502 Bad Gateway</title></head>
<body bgcolor="white">
<center><h1>502 Bad Gateway</h1></center>
<hr><center>nginx/1.6.2</center>
</body>
</html>
]"
2016-04-26 10:42:33,030 (__init__.py:199 MainThread) ERROR - TeleBot: "A request to the Telegram API was unsuccessful. The server returned HTTP 502 Bad Gateway. Response body:
[<html>
<head><title>502 Bad Gateway</title></head>
<body bgcolor="white">
<center><h1>502 Bad Gateway</h1></center>
<hr><center>nginx/1.6.2</center>
</body>
</html>
]"
